Traceback (most recent call last):
  File "/home/csah2k/Documents/rss-crawler/services/stock.py", line 77, in index_stock_symbols
    try:
  File "/home/csah2k/.local/lib/python3.8/site-packages/retrying.py", line 49, in wrapped_f
    return Retrying(*dargs, **dkw).call(f, *args, **kw)
  File "/home/csah2k/.local/lib/python3.8/site-packages/retrying.py", line 212, in call
    raise attempt.get()
  File "/home/csah2k/.local/lib/python3.8/site-packages/retrying.py", line 247, in get
    six.reraise(self.value[0], self.value[1], self.value[2])
  File "/usr/lib/python3/dist-packages/six.py", line 703, in reraise
    raise value
  File "/home/csah2k/.local/lib/python3.8/site-packages/retrying.py", line 200, in call
    attempt = Attempt(fn(*args, **kwargs), attempt_number, False)
  File "/home/csah2k/Documents/rss-crawler/services/stock.py", line 36, in get_symbol_profile
    raise error
  File "/home/csah2k/Documents/rss-crawler/services/stock.py", line 33, in get_symbol_profile
    return response.json()
  File "/usr/lib/python3/dist-packages/requests/models.py", line 897, in json
    return complexjson.loads(self.text, **kwargs)
  File "/usr/lib/python3/dist-packages/simplejson/__init__.py", line 518, in loads
    return _default_decoder.decode(s)
  File "/usr/lib/python3/dist-packages/simplejson/decoder.py", line 370, in decode
    obj, end = self.raw_decode(s)
  File "/usr/lib/python3/dist-packages/simplejson/decoder.py", line 400, in raw_decode
    return self.scan_once(s, idx=_w(s, idx).end())
simplejson.errors.JSONDecodeError: Expecting value: line 1 column 1 (char 0)

During handling of the above exception, another exception occurred:

Traceback (most recent call last):
  File "main.py", line 41, in <module>
    
  File "/home/csah2k/.local/lib/python3.8/site-packages/plac_core.py", line 367, in call
    cmd, result = parser.consume(arglist)
  File "/home/csah2k/.local/lib/python3.8/site-packages/plac_core.py", line 232, in consume
    return cmd, self.func(*(args + varargs + extraopts), **kwargs)
  File "main.py", line 28, in main
    
  File "/home/csah2k/Documents/rss-crawler/services/stock.py", line 60, in index_stocks_symbols
    threads.append(self.executor.submit(self.index_stock_symbols, _e))
  File "/usr/lib/python3.8/concurrent/futures/_base.py", line 439, in result
    return self.__get_result()
  File "/usr/lib/python3.8/concurrent/futures/_base.py", line 388, in __get_result
    raise self._exception
  File "/usr/lib/python3.8/concurrent/futures/thread.py", line 57, in run
    result = self.fn(*self.args, **self.kwargs)
  File "/home/csah2k/.local/lib/python3.8/site-packages/retrying.py", line 49, in wrapped_f
    return Retrying(*dargs, **dkw).call(f, *args, **kw)
  File "/home/csah2k/.local/lib/python3.8/site-packages/retrying.py", line 212, in call
    raise attempt.get()
  File "/home/csah2k/.local/lib/python3.8/site-packages/retrying.py", line 247, in get
    six.reraise(self.value[0], self.value[1], self.value[2])
  File "/usr/lib/python3/dist-packages/six.py", line 703, in reraise
    raise value
  File "/home/csah2k/.local/lib/python3.8/site-packages/retrying.py", line 200, in call
    attempt = Attempt(fn(*args, **kwargs), attempt_number, False)
  File "/home/csah2k/Documents/rss-crawler/services/stock.py", line 108, in index_stock_symbols
    }  
AttributeError: 'list' object has no attribute 'text'
